Workbook

Sheet Shipping Line Items
A1: shipping_code | B1: terminal_code | C1: product_code | D1: line_item_type_name | E1: index_code | F1: price_day | G1: line_item_adder | H1: line_item_percent
A2: Shipping_Aberdeen SD_SD00_8701 | B2: SD00 | C2: 8701 | D2: Product | E2: PL_C_PG-AAXIX00-UNL SUB | F2: Prior Day | G2: 0 | H2: 1
A3: Shipping_Aberdeen SD_SD00_8701 | B3: SD00 | C3: 8701 | D3: Combined Adder | E3: NULL | F3: NULL | G3: 0.1135 | H3: 1
A4: Shipping_Aberdeen SD_SD00_8710 | B4: SD00 | C4: 8710 | D4: Product | E4: PL_C_PG-AAXIX00-UNL SUB | F4: Prior Day | G4: 0 | H4: 0.9
A5: Shipping_Aberdeen SD_SD00_8710 | B5: SD00 | C5: 8710 | D5: Ethanol | E5: OP_A_OS-CHI-ETHANOL | F5: Prior Day | G5: 0 | H5: 0.1
A6: Shipping_Aberdeen SD_SD00_8710 | B6: SD00 | C6: 8710 | D6: Combined Adder | E6: NULL | F6: NULL | G6: 0.0943 | H6: 1
A7: Shipping_Aberdeen SD_SD00_8710 | B7: SD00 | C7: 8710 | D7: RIN | E7: OP_A_OS-USA-RIN_CURRENT | F7: Prior Day | G7: 0 | H7: -0.1
A8: Shipping_Aberdeen SD_SD00_9101 | B8: SD00 | C8: 9101 | D8: Product | E8: PL_C_PG-PGABD00-UNL91 | F8: Prior Day | G8: 0 | H8: 1
A9: Shipping_Aberdeen SD_SD00_9101 | B9: SD00 | C9: 9101 | D9: Combined Adder | E9: NULL | F9: NULL | G9: 0.1135 | H9: 1
A10: Shipping_Aberdeen SD_SD00_9110 | B10: SD00 | C10: 9110 | D10: Product | E10: PL_C_PG-PGABD00-UNL91 | F10: Prior Day | G10: 0 | H10: 0.9
A11: Shipping_Aberdeen SD_SD00_9110 | B11: SD00 | C11: 9110 | D11: Ethanol | E11: OP_A_OS-CHI-ETHANOL | F11: Prior Day | G11: 0 | H11: 0.1
A12: Shipping_Aberdeen SD_SD00_9110 | B12: SD00 | C12: 9110 | D12: Combined Adder | E12: NULL | F12: NULL | G12: 0.0943 | H12: 1
A13: Shipping_Aberdeen SD_SD00_9110 | B13: SD00 | C13: 9110 | D13: RIN | E13: OP_A_OS-USA-RIN_CURRENT | F13: Prior Day | G13: 0 | H13: -0.1
... A3309: Shipping_Zionsville IN_IN23_9310 | B3309: IN23 | C3309: 9310 | D3309: RIN | E3309: OP_A_OS-USA-RIN_CURRENT | F3309: Prior Day | G3309: 0 | H3309: -0.1

Sheet Costing Detail
G1: ETH | H1: ETH | I1: ETH | J1: ETH | K1: ETH | L1: ETH | M1: ETH | N1: ETH | O1: ETH | P1: ETH | Q1: ETH | R1: ETH | S1: ETH | T1: ETH | U1: GAS | V1: GAS | W1: GAS | X1: GAS | Y1: GAS | Z1: GAS | AA1: GAS | AB1: GAS | AC1: GAS | AD1: GAS | AE1: Combined Adders
G2: TML | H2: TML | I2: TML | J2: TML | K2: TPT | L2: TPT | M2: TPT | N2: TPT | O2: TPT | P2: TPT | Q2: TPT | R2: TPT | S2: TPT | U2: TML | V2: TML | W2: TML | X2: TML | Y2: TPT | Z2: TPT | AA2: TPT | AB2: TPT | AC2: TPT
A3: State | B3: Terminal City | C3: Terminal Market | D3: Region | E3: Terminal Code | F3: EN Terminal Name | G3: facilities charge | H3: throughput | I3: terminaling estimate | J3: Subtotal | K3: tariff | L3: tvm | M3: basis | N3: fuel surcharge | O3: transload | P3: truck freight | Q3: wholesale margin | R3: transportation estimate | S3: Subtotal | T3: Total | U3: throughput | V3: generic additive | W3: terminaling estimate | X3: Subtotal | Y3: tariff | Z3: tvm | AA3: line loss | AB3: transportation estimate | AC3: Subtotal | AD3: Total | AE3: Clear Gas | AF3: E10 | AG3: E15 | AH3: Notes
A4: AL | B4: Birmingham AL | C4: Birmingham AL | D4: PADD 3 | E4: AL06 | F4: AL Birmingham - Buckeye - 2309 | G4: 0 | H4: 0 | I4: 0.0115 | J4: =SUM(G4:I4) -> 0.0115 | K4: 0.183867 | L4: 0.002319 | M4: -0.055 | N4: 0.005 | O4: 0.0125 | P4: 0.015 | Q4: 0.02 | R4: 0 | S4: =SUM(K4:R4) -> 0.183686 | T4: =J4+S4 -> 0.195186 | U4: 0 | V4: 0 | W4: 0.0115 | X4: =SUM(U4:W4) -> 0.0115 | Y4: 0.032955 | Z4: 0.002487 | AA4: 0.003 | AB4: 0 | AC4: =SUM(Y4:AB4) -> 0.038442 | AD4: =AC4+X4 -> 0.049942 | AE4: =0*T4+1*AD4 -> 0.049942 | AF4: =0.1*T4+0.9*AD4 -> 0.0644664 | AG4: =0.15*T4+0.85*AD4 -> 0.0717286 | AI4: =SUMIFS('Paths and Tariffs'!Q:Q,'Paths and Tariffs'!E:E,'Costing Detail'!E4,'Paths and Tariffs'!G:G,"GAS",'Paths and Tariffs'!N:N,1,'Paths and Tariffs'!M:M,1) -> 0.032955
A5: AL | B5: Boligee AL | C5: Boligee AL | D5: PADD 3 | E5: AL29 | F5: AL Boligee - ERPC - 0001 | G5: 0 | H5: 0 | I5: 0.0115 | J5: =SUM(G5:I5) -> 0.0115 | K5: 0.184845 | L5: 0.002246 | M5: -0.055 | N5: 0.005 | O5: 0.0125 | P5: 0.015 | Q5: 0.02 | R5: 0 | S5: =SUM(K5:R5) -> 0.184591 | T5: =J5+S5 -> 0.196091 | U5: 0 | V5: 0 | W5: 0.0115 | X5: =SUM(U5:W5) -> 0.0115 | Y5: 0.032955 | Z5: 0.00223 | AA5: 0.003 | AB5: 0 | AC5: =SUM(Y5:AB5) -> 0.038185 | AD5: =AC5+X5 -> 0.049685 | AE5: =0*T5+1*AD5 -> 0.049685 | AF5: =0.1*T5+0.9*AD5 -> 0.0643256 | AG5: =0.15*T5+0.85*AD5 -> 0.0716459 | AI5: =SUMIFS('Paths and Tariffs'!Q:Q,'Paths and Tariffs'!E:E,'Costing Detail'!E5,'Paths and Tariffs'!G:G,"GAS",'Paths and Tariffs'!N:N,1,'Paths and Tariffs'!M:M,1) -> 0.032955
A6: AL | B6: Montgomery AL | C6: Montgomery AL | D6: PADD 3 | E6: AL02 | F6: AL Montgomery - Buckeye - 2304 | G6: 0 | H6: 0 | I6: 0.0115 | J6: =SUM(G6:I6) -> 0.0115 | K6: 0.1913 | L6: 0.002421 | M6: -0.055 | N6: 0.005 | O6: 0.0125 | P6: 0.015 | Q6: 0.02 | R6: 0 | S6: =SUM(K6:R6) -> 0.191221 | T6: =J6+S6 -> 0.202721 | U6: 0 | V6: 0 | W6: 0.0115 | X6: =SUM(U6:W6) -> 0.0115 | Y6: 0.035152 | Z6: 0.001944 | AA6: 0.003 | AB6: 0 | AC6: =SUM(Y6:AB6) -> 0.040096 | AD6: =AC6+X6 -> 0.051596 | AE6: =0*T6+1*AD6 -> 0.051596 | AF6: =0.1*T6+0.9*AD6 -> 0.0667085 | AG6: =0.15*T6+0.85*AD6 -> 0.07426475 | AI6: =SUMIFS('Paths and Tariffs'!Q:Q,'Paths and Tariffs'!E:E,'Costing Detail'!E6,'Paths and Tariffs'!G:G,"GAS",'Paths and Tariffs'!N:N,1,'Paths and Tariffs'!M:M,1) -> 0.035152
A7: AR | B7: Fort Smith AR | C7: Fort Smith AR | D7: PADD 3 | E7: AR01 | F7: AR Fort Smith - Mag - 2453 | G7: 0 | H7: 0 | I7: 0.0115 | J7: =SUM(G7:I7) -> 0.0115 | K7: 0.2115 | L7: 0.002291 | M7: -0.125 | N7: 0.005 | O7: 0.0125 | P7: 0.015 | Q7: 0.02 | R7: 0 | S7: =SUM(K7:R7) -> 0.141291 | T7: =J7+S7 -> 0.152791 | U7: 0 | V7: 0 | W7: 0 | X7: =SUM(U7:W7) -> 0 | Y7: 0.110055 | Z7: 0.002568 | AA7: 0.003 | AB7: 0 | AC7: =SUM(Y7:AB7) -> 0.115623 | AD7: =AC7+X7 -> 0.115623 | AE7: =0*T7+1*AD7 -> 0.115623 | AF7: =0.1*T7+0.9*AD7 -> 0.1193398 | AG7: =0.15*T7+0.85*AD7 -> 0.1211982 | AI7: =SUMIFS('Paths and Tariffs'!Q:Q,'Paths and Tariffs'!E:E,'Costing Detail'!E7,'Paths and Tariffs'!G:G,"GAS",'Paths and Tariffs'!N:N,1,'Paths and Tariffs'!M:M,1) -> 0.110055
A8: AR | B8: North Little Rock AR | C8: Little Rock AR | D8: PADD 3 | E8: AR02 | F8: AR North Little Rock - Mag - 2456 | G8: 0 | H8: 0 | I8: 0.0115 | J8: =SUM(G8:I8) -> 0.0115 | K8: 0.2115 | L8: 0.002341 | M8: -0.125 | N8: 0.005 | O8: 0.0125 | P8: 0.015 | Q8: 0.02 | R8: 0 | S8: =SUM(K8:R8) -> 0.141341 | T8: =J8+S8 -> 0.152841 | U8: 0 | V8: 0 | W8: 0.0115 | X8: =SUM(U8:W8) -> 0.0115 | Y8: 0.086612 | Z8: 0.00314 | AA8: 0.003 | AB8: 0 | AC8: =SUM(Y8:AB8) -> 0.092752 | AD8: =AC8+X8 -> 0.104252 | AE8: =0*T8+1*AD8 -> 0.104252 | AF8: =0.1*T8+0.9*AD8 -> 0.1091109 | AG8: =0.15*T8+0.85*AD8 -> 0.11154035 | AI8: =SUMIFS('Paths and Tariffs'!Q:Q,'Paths and Tariffs'!E:E,'Costing Detail'!E8,'Paths and Tariffs'!G:G,"GAS",'Paths and Tariffs'!N:N,1,'Paths and Tariffs'!M:M,1) -> 0.086612
A9: AR | B9: West Memphis AR | C9: West Memphis AR | D9: PADD 3 | E9: AR08 | F9: AR West Memphis - Valero - 2463 | G9: 0 | H9: 0 | I9: 0.0115 | J9: =SUM(G9:I9) -> 0.0115 | K9: 0.217362 | L9: 0.002366 | M9: -0.125 | N9: 0.005 | O9: 0.0125 | P9: 0.015 | Q9: 0.02 | R9: 0 | S9: =SUM(K9:R9) -> 0.147228 | T9: =J9+S9 -> 0.158728 | U9: 0 | V9: 0 | W9: 0.0115 | X9: =SUM(U9:W9) -> 0.0115 | Y9: 0.080464 | Z9: 0.002475 | AA9: 0.003 | AB9: 0 | AC9: =SUM(Y9:AB9) -> 0.085939 | AD9: =AC9+X9 -> 0.097439 | AE9: =0*T9+1*AD9 -> 0.097439 | AF9: =0.1*T9+0.9*AD9 -> 0.1035679 | AG9: =0.15*T9+0.85*AD9 -> 0.10663235 | AI9: =SUMIFS('Paths and Tariffs'!Q:Q,'Paths and Tariffs'!E:E,'Costing Detail'!E9,'Paths and Tariffs'!G:G,"GAS",'Paths and Tariffs'!N:N,1,'Paths and Tariffs'!M:M,1) -> 0.080464
A10: AR | B10: Rogers AR | C10: Rogers AR | D10: PADD 3 | E10: AR11 | F10: AR Rogers - Mag - 2467 | G10: 0 | H10: 0 | I10: 0.0115 | J10: =SUM(G10:I10) -> 0.0115 | K10: 0.182984 | L10: 0.002246 | M10: -0.125 | N10: 0.005 | O10: 0.0125 | P10: 0.015 | Q10: 0.02 | R10: 0 | S10: =SUM(K10:R10) -> 0.11273 | T10: =J10+S10 -> 0.12423 | U10: 0 | V10: 0 | W10: 0.0115 | X10: =SUM(U10:W10) -> 0.0115 | Y10: 0.163576 | Z10: 0.003494 | AA10: 0.003 | AB10: 0 | AC10: =SUM(Y10:AB10) -> 0.17007 | AD10: =AC10+X10 -> 0.18157 | AE10: =0*T10+1*AD10 -> 0.18157 | AF10: =0.1*T10+0.9*AD10 -> 0.175836 | AG10: =0.15*T10+0.85*AD10 -> 0.172969 | AI10: =SUMIFS('Paths and Tariffs'!Q:Q,'Paths and Tariffs'!E:E,'Costing Detail'!E10,'Paths and Tariffs'!G:G,"GAS",'Paths and Tariffs'!N:N,1,'Paths and Tariffs'!M:M,1) -> 0.163576
A11: AZ | B11: Phoenix AZ | C11: Phoenix AZ | D11: PADD 5 | E11: AZ03 | F11: AZ Phoenix - SFPP - 4304 | G11: 0.05 | H11: 0 | I11: 0 | J11: =SUM(G11:I11) -> 0.05 | K11: 0.206333 | L11: 0.002819 | M11: -0.125 | N11: 0.005 | O11: 0.0125 | P11: 0.015 | Q11: 0.02 | R11: 0 | S11: =SUM(K11:R11) -> 0.136652 | T11: =J11+S11 -> 0.186652 | U11: 0.00875 | V11: 0.002262 | W11: 0 | X11: =SUM(U11:W11) -> 0.011012 | Y11: 0.044969 | Z11: 0.001948 | AA11: 0.003 | AB11: 0 | AC11: =SUM(Y11:AB11) -> 0.049917 | AD11: =AC11+X11 -> 0.060929 | AE11: =0*T11+1*AD11 -> 0.060929 | AF11: =0.1*T11+0.9*AD11 -> 0.0735013 | AG11: =0.15*T11+0.85*AD11 -> 0.07978745 | AI11: =SUMIFS('Paths and Tariffs'!Q:Q,'Paths and Tariffs'!E:E,'Costing Detail'!E11,'Paths and Tariffs'!G:G,"GAS",'Paths and Tariffs'!N:N,1,'Paths and Tariffs'!M:M,1) -> 0.044969
A12: AZ | B12: Tucson AZ | C12: Tucson AZ | D12: PADD 5 | E12: AZ05 | F12: AZ Tucson - SFPP - 4310 | G12: 0.05 | H12: 0 | I12: 0 | J12: =SUM(G12:I12) -> 0.05 | K12: 0.229667 | L12: 0.002753 | M12: -0.125 | N12: 0.005 | O12: 0.0125 | P12: 0.015 | Q12: 0.02 | R12: 0 | S12: =SUM(K12:R12) -> 0.15992 | T12: =J12+S12 -> 0.20992 | U12: 0.00875 | V12: 0.002262 | W12: 0 | X12: =SUM(U12:W12) -> 0.011012 | Y12: 0.033007 | Z12: 0.001599 | AA12: 0.003 | AB12: 0 | AC12: =SUM(Y12:AB12) -> 0.037606 | AD12: =AC12+X12 -> 0.048618 | AE12: =0*T12+1*AD12 -> 0.048618 | AF12: =0.1*T12+0.9*AD12 -> 0.0647482 | AG12: =0.15*T12+0.85*AD12 -> 0.0728133 | AI12: =SUMIFS('Paths and Tariffs'!Q:Q,'Paths and Tariffs'!E:E,'Costing Detail'!E12,'Paths and Tariffs'!G:G,"GAS",'Paths and Tariffs'!N:N,1,'Paths and Tariffs'!M:M,1) -> 0.033007
A13: CA | B13: Colton CA | C13: Colton CA | D13: PADD 5 | E13: CA09 | F13: CA Colton - SFPP - 4757 | G13: 0.05 | H13: 0 | I13: 0 | J13: =SUM(G13:I13) -> 0.05 | K13: 0.294167 | L13: 0.002899 | M13: -0.125 | N13: 0.005 | O13: 0.0125 | P13: 0.015 | Q13: 0.02 | R13: 0 | S13: =SUM(K13:R13) -> 0.224566 | T13: =J13+S13 -> 0.274566 | U13: 0.00875 | V13: 0.002262 | W13: 0 | X13: =SUM(U13:W13) -> 0.011012 | Y13: 0.00866 | Z13: 0.000939 | AA13: 0.003 | AB13: 0 | AC13: =SUM(Y13:AB13) -> 0.012599 | AD13: =AC13+X13 -> 0.023611 | AE13: =0*T13+1*AD13 -> 0.023611 | AF13: =0.1*T13+0.9*AD13 -> 0.0487065 | AG13: =0.15*T13+0.85*AD13 -> 0.06125425 | AI13: =SUMIFS('Paths and Tariffs'!Q:Q,'Paths and Tariffs'!E:E,'Costing Detail'!E13,'Paths and Tariffs'!G:G,"GAS",'Paths and Tariffs'!N:N,1,'Paths and Tariffs'!M:M,1) -> 0.00866
A14: CA | B14: Fresno CA | C14: Fresno CA | D14: PADD 5 | E14: CA58 | F14: CA Fresno - SFPP - 4651 | G14: 0.05 | H14: 0 | I14: 0 | J14: =SUM(G14:I14) -> 0.05 | K14: 0.298167 | L14: 0.002965 | M14: -0.125 | N14: 0.005 | O14: 0.0125 | P14: 0.015 | Q14: 0.02 | R14: 0 | S14: =SUM(K14:R14) -> 0.228632 | T14: =J14+S14 -> 0.278632 | U14: 0.00875 | V14: 0.002262 | W14: 0 | X14: =SUM(U14:W14) -> 0.011012 | Y14: 0.031295 | Z14: 0.001259 | AA14: 0.003 | AB14: 0 | AC14: =SUM(Y14:AB14) -> 0.035554 | AD14: =AC14+X14 -> 0.046566 | AE14: =0*T14+1*AD14 -> 0.046566 | AF14: =0.1*T14+0.9*AD14 -> 0.0697726 | AG14: =0.15*T14+0.85*AD14 -> 0.0813759 | AI14: =SUMIFS('Paths and Tariffs'!Q:Q,'Paths and Tariffs'!E:E,'Costing Detail'!E14,'Paths and Tariffs'!G:G,"GAS",'Paths and Tariffs'!N:N,1,'Paths and Tariffs'!M:M,1) -> 0.031295
A15: CA | B15: Imperial CA | C15: Imperial CA | D15: PADD 5 | E15: CA13 | F15: CA Imperial - SFPP - 4763 | G15: 0.05 | H15: 0 | I15: 0 | J15: =SUM(G15:I15) -> 0.05 | K15: 0.2975 | L15: 0.002938 | M15: -0.125 | N15: 0.005 | O15: 0.0125 | P15: 0.015 | Q15: 0.02 | R15: 0 | S15: =SUM(K15:R15) -> 0.227938 | T15: =J15+S15 -> 0.277938 | U15: 0.00875 | V15: 0.002262 | W15: 0 | X15: =SUM(U15:W15) -> 0.011012 | Y15: 0.021024 | Z15: 0.001386 | AA15: 0.003 | AB15: 0 | AC15: =SUM(Y15:AB15) -> 0.02541 | AD15: =AC15+X15 -> 0.036422 | AE15: =0*T15+1*AD15 -> 0.036422 | AF15: =0.1*T15+0.9*AD15 -> 0.0605736 | AG15: =0.15*T15+0.85*AD15 -> 0.0726494 | AI15: =SUMIFS('Paths and Tariffs'!Q:Q,'Paths and Tariffs'!E:E,'Costing Detail'!E15,'Paths and Tariffs'!G:G,"GAS",'Paths and Tariffs'!N:N,1,'Paths and Tariffs'!M:M,1) -> 0.021026
... A230: WY | B230: Cheyenne WY | C230: Cheyenne WY | D230: PADD 4 | E230: WY03 | F230: WY Cheyenne - Mag - 4053 | G230: 0 | H230: 0 | I230: 0.0115 | J230: =SUM(G230:I230) -> 0.0115 | K230: 0.184477 | L230: 0.002326 | M230: -0.125 | N230: 0.005 | O230: 0.0125 | P230: 0.015 | Q230: 0.02 | R230: 0 | S230: =SUM(K230:R230) -> 0.114303 | T230: =J230+S230 -> 0.125803 | U230: 0 | V230: 0 | W230: 0.0115 | X230: =SUM(U230:W230) -> 0.0115 | Y230: 0.033731 | Z230: 0.001247 | AA230: 0.003 | AB230: 0 | AC230: =SUM(Y230:AB230) -> 0.037978 | AD230: =AC230+X230 -> 0.049478 | AE230: =0*T230+1*AD230 -> 0.049478 | AF230: =0.1*T230+0.9*AD230 -> 0.0571105 | AG230: =0.15*T230+0.85*AD230 -> 0.06092675 | AI230: =SUMIFS('Paths and Tariffs'!Q:Q,'Paths and Tariffs'!E:E,'Costing Detail'!E230,'Paths and Tariffs'!G:G,"GAS",'Paths and Tariffs'!N:N,1,'Paths and Tariffs'!M:M,1) -> 0.033731

Sheet Paths and Tariffs
A1: terminal_state | B1: terminal_city_code | C1: terminal_market_code | D1: region | E1: terminal_code | F1: en_terminal_name | G1: product_category_code | H1: shipping_path_code | I1: path_origin | J1: path_destination | K1: path_length | L1: path_time | M1: term_path_link | N1: published terminal | O1: tariff_code | P1: tariff_library_name | Q1: tariff_value
F2: IL Amboy - Growmark - 3319 | G2: GAS | H2: BP WHW Path 4 | I2: BP WHW - Whiting Station | J2: MG IA1 - Menard | K2: 177 | L2: 38.41 | M2: 1 | N2: 0
F3: IL Amboy - Growmark - 3319 | G3: ETH | H3: UP Path 151 | I3: UP - UP COUNCIL BLUFFS IA | J3: UP - UP Amboy IL | K3: 338 | L3: 15.37 | M3: 0 | N3: 0 | O3: UP_tariff_2 | P3: UP_1023_estimated | Q3: 0.18279
F4: TN Dickson - Buckeye - 2244 | G4: GAS | H4: BP WHD Path 1 | I4: BP WHD - Whiting Station | J4: BP WHD - Burns | K4: 409 | L4: 88.98 | M4: 1 | N4: 0 | O4: BP_39 | P4: BP WHD_0723_278.17.0 | Q4: 0.0715
F5: TN Dickson - Buckeye - 2244 | G5: ETH | H5: CSX Path 26 | I5: CSX - CSX Chicago IL Bedford Park Yard | J5: CSX - CSX Dickson TN | K5: 560 | L5: 25.44 | M5: 1 | N5: 0 | O5: CSX_tariff_26 | P5: CSX_1023_estimated | Q5: 0.183628
F6: TN Knoxville - PBF - 2214-2243 | G6: ETH | H6: NS Path 134 | I6: NS - NS DECATUR IL | J6: NS - NS KNOXVILLE TN | K6: 540 | L6: 24.56 | M6: 1 | N6: 0 | O6: NS_NS DECATUR IL-NS_NS KNOXVILLE TN | P6: NS_1023_WB 336649 | Q6: 0.1979
F7: TN Knoxville - PBF - 2214-2243 | G7: ETH | H7: NS Path 59 | I7: NS - NS Chicago IL Calumet Yard | J7: NS - NS KNOXVILLE TN | K7: 612 | L7: 27.82 | M7: 0 | N7: 0 | O7: NS_NS Chicago IL-NS_NS KNOXVILLE TN
F8: TX Brownsville - SRPE - 2717 | G8: ETH | H8: BNSF Path 17 | I8: BNSF - BNSF Council Bluffs IA Depot | J8: BNSF - BNSF Brownsville TX | K8: 1438 | L8: 65.35 | M8: 1 | N8: 0 | O8: BNSF_tariff_17 | P8: BNSF_1023_estimated | Q8: 0.292343
F9: TX Brownsville - SRPE - 2717 | G9: ETH | H9: UP Path 180 | I9: UP - UP COUNCIL BLUFFS IA | J9: UP - UP BROWNSVILLE TX | K9: 1267 | L9: 57.59 | M9: 0 | N9: 0 | O9: UP_tariff_180 | P9: UP_1023_estimated | Q9: 0.2605
F10: TX Midland - Mag - 2766 | G10: GAS | H10: MG SOR Path 17 | I10: MG SOR - MG Tulsa West Tulsa | J10: MG SOR - MG Midland Midland | K10: 726 | L10: 157.87 | M10: 0 | N10: 0 | O10: MG_126 | P10: MG S ORIGS_0723_161.54.0 | Q10: 0.175729
F11: TX Midland - Mag - 2766 | G11: GAS | H11: MG SOR Path 3 | I11: MG SOR - MG Wynnedwood Gavin | J11: MG SOR - MG Midland Midland | K11: 565 | L11: 122.85 | M11: 0 | N11: 0
F12: TX Midland - Mag - 2766 | G12: GAS | I12: - | J12: MG EP - MG Midland Midland | M12: 0 | N12: 0
F13: TX Midland - Mag - 2766 | G13: ETH | H13: UP Path 208 | I13: UP - UP COUNCIL BLUFFS IA | J13: UP - UP MIDLAND TX | K13: 1023 | L13: 46.5 | M13: 1 | N13: 0 | O13: UP_tariff_208 | P13: UP_1023_estimated | Q13: 0.2455
F14: TX Orla - HF Sinclair - 2762 | G14: ETH | H14: UP Path 213 | I14: UP - UP COUNCIL BLUFFS IA | J14: UP - UP PECOS TX | K14: 801 | L14: 36.41 | M14: 1 | N14: 0 | O14: UP_213 | P14: UP_1023_2028-A | Q14: 0.2455
A15: AL | B15: Oxford AL | C15: Anniston/Oxford AL | D15: PADD 3 | E15: AL18 | F15: AL Anniston - Murphy - 2333 | G15: GAS | H15: CPL Path 20 | I15: CPL - Pasadena Injection (Remote) | J15: CPL - Oxford Delivery Facility | K15: 664 | L15: 144.35 | M15: 1 | N15: 0 | O15: CPL_Houston-CPL_Oxford | P15: CPL_0723_99.83.0 | Q15: 0.035795
A16: AL | B16: Oxford AL | C16: Anniston/Oxford AL | D16: PADD 3 | E16: AL18 | F16: AL Anniston - Murphy - 2333 | G16: GAS | H16: PPL Path 13 | I16: PPL - Baton Rouge | J16: PPL - Oxford | K16: 405 | L16: 88.04 | M16: 0 | N16: 0 | O16: PPL_24 | P16: PPL_23_155.38.0_154.17.0 | Q16: 0.031502
A17: AL | B17: Oxford AL | C17: Anniston/Oxford AL | D17: PADD 3 | E17: AL18 | F17: AL Anniston - Murphy - 2333 | G17: ETH | H17: NS Path 1 | I17: NS - NS Chicago IL Calumet Yard | J17: NS - NS ANNISTON AL | K17: 779 | L17: 35.42 | M17: 0 | N17: 0 | O17: NS_NS Chicago IL-NS_NS ANNISTON AL
A18: AL | B18: Oxford AL | C18: Anniston/Oxford AL | D18: PADD 3 | E18: AL18 | F18: AL Anniston - Murphy - 2333 | G18: ETH | H18: NS Path 116 | I18: NS - NS DECATUR IL | J18: NS - NS ANNISTON AL | K18: 648 | L18: 29.47 | M18: 1 | N18: 0 | O18: NS_NS DECATUR IL-NS_NS ANNISTON AL | P18: NS_1023_WB 336649 | Q18: 0.183867
A19: AL | B19: Birmingham AL | C19: Birmingham AL | D19: PADD 3 | E19: AL01 | F19: AL Birmingham - Citgo - 2302 | G19: GAS | H19: CPL Path 18 | I19: CPL - Pasadena Injection (Remote) | J19: CPL - Birmingham Delivery Facility | K19: 603 | L19: 131 | M19: 1 | N19: 0 | O19: CPL_Houston-CPL_Birmingham | P19: CPL_0723_99.83.0 | Q19: 0.032955
A20: AL | B20: Birmingham AL | C20: Birmingham AL | D20: PADD 3 | E20: AL01 | F20: AL Birmingham - Citgo - 2302 | G20: GAS | H20: PPL Path 12 | I20: PPL - Baton Rouge | J20: PPL - Birmingham | K20: 349 | L20: 75.93 | M20: 0 | N20: 0 | O20: PPL_6 | P20: PPL_23_155.38.0_154.17.0 | Q20: 0.028102
A21: AL | B21: Birmingham AL | C21: Birmingham AL | D21: PADD 3 | E21: AL01 | F21: AL Birmingham - Citgo - 2302 | G21: ETH | H21: CSX USRT PATH 16 | I21: CSX - CSX Indianapolis IN Avon Yard | J21: CSX - CSX Birmingham AL Boyles Yard | K21: 450 | L21: 0 | M21: 0 | N21: 0
A22: AL | B22: Birmingham AL | C22: Birmingham AL | D22: PADD 3 | E22: AL01 | F22: AL Birmingham - Citgo - 2302 | G22: ETH | H22: CSX USRT PATH 4 | I22: CSX - CSX Chicago IL Bedford Park Yard | J22: CSX - CSX Birmingham AL Boyles Yard | K22: 598 | L22: 0 | M22: 0 | N22: 0
A23: AL | B23: Birmingham AL | C23: Birmingham AL | D23: PADD 3 | E23: AL01 | F23: AL Birmingham - Citgo - 2302 | G23: ETH | H23: NS Path 117 | I23: NS - NS DECATUR IL | J23: NS - NS Birmingham AL Norris Yard | K23: 631 | L23: 28.7 | M23: 1 | N23: 0 | O23: NS_NS DECATUR IL-NS_NS BIRMINGHAM AL | P23: NS_1023_WB 336649 | Q23: 0.183867
A24: AL | B24: Birmingham AL | C24: Birmingham AL | D24: PADD 3 | E24: AL01 | F24: AL Birmingham - Citgo - 2302 | G24: ETH | H24: NS USRT PATH 3 | I24: NS - NS Chicago IL Calumet Yard | J24: NS - NS Birmingham AL Norris Yard | K24: 594 | L24: 0 | M24: 0 | N24: 0 | O24: NS_NS Chicago IL-NS_NS BIRMINGHAM AL
A25: AL | B25: Birmingham AL | C25: Birmingham AL | D25: PADD 3 | E25: AL01 | F25: AL Birmingham - Citgo - 2302 | G25: ETH | H25: NS USRT PATH 9 | I25: NS - NS Clymers IN Anderson Ethanol | J25: NS - NS Birmingham AL Norris Yard | K25: 521 | L25: 0 | M25: 0 | N25: 0
A26: AL | B26: Birmingham AL | C26: Birmingham AL | D26: PADD 3 | E26: AL03 | F26: AL Birmingham - MPC - 2306 | G26: GAS | H26: CPL Path 18 | I26: CPL - Pasadena Injection (Remote) | J26: CPL - Birmingham Delivery Facility | K26: 603 | L26: 131 | M26: 1 | N26: 0 | O26: CPL_Houston-CPL_Birmingham | P26: CPL_0723_99.83.0 | Q26: 0.032955
A27: AL | B27: Birmingham AL | C27: Birmingham AL | D27: PADD 3 | E27: AL03 | F27: AL Birmingham - MPC - 2306 | G27: GAS | H27: PPL Path 12 | I27: PPL - Baton Rouge | J27: PPL - Birmingham | K27: 349 | L27: 75.93 | M27: 0 | N27: 0 | O27: PPL_6 | P27: PPL_23_155.38.0_154.17.0 | Q27: 0.028102
A28: AL | B28: Birmingham AL | C28: Birmingham AL | D28: PADD 3 | E28: AL03 | F28: AL Birmingham - MPC - 2306 | G28: ETH | H28: CSX USRT PATH 16 | I28: CSX - CSX Indianapolis IN Avon Yard | J28: CSX - CSX Birmingham AL Boyles Yard | K28: 450 | L28: 0 | M28: 0 | N28: 0
A29: AL | B29: Birmingham AL | C29: Birmingham AL | D29: PADD 3 | E29: AL03 | F29: AL Birmingham - MPC - 2306 | G29: ETH | H29: CSX USRT PATH 4 | I29: CSX - CSX Chicago IL Bedford Park Yard | J29: CSX - CSX Birmingham AL Boyles Yard | K29: 598 | L29: 0 | M29: 0 | N29: 0
A30: AL | B30: Birmingham AL | C30: Birmingham AL | D30: PADD 3 | E30: AL03 | F30: AL Birmingham - MPC - 2306 | G30: ETH | H30: NS Path 117 | I30: NS - NS DECATUR IL | J30: NS - NS Birmingham AL Norris Yard | K30: 631 | L30: 28.7 | M30: 1 | N30: 0 | O30: NS_NS DECATUR IL-NS_NS BIRMINGHAM AL | P30: NS_1023_WB 336649 | Q30: 0.183867
A31: AL | B31: Birmingham AL | C31: Birmingham AL | D31: PADD 3 | E31: AL03 | F31: AL Birmingham - MPC - 2306 | G31: ETH | H31: NS USRT PATH 3 | I31: NS - NS Chicago IL Calumet Yard | J31: NS - NS Birmingham AL Norris Yard | K31: 594 | L31: 0 | M31: 0 | N31: 0 | O31: NS_NS Chicago IL-NS_NS BIRMINGHAM AL
A32: AL | B32: Birmingham AL | C32: Birmingham AL | D32: PADD 3 | E32: AL03 | F32: AL Birmingham - MPC - 2306 | G32: ETH | H32: NS USRT PATH 9 | I32: NS - NS Clymers IN Anderson Ethanol | J32: NS - NS Birmingham AL Norris Yard | K32: 521 | L32: 0 | M32: 0 | N32: 0
A33: AL | B33: Birmingham AL | C33: Birmingham AL | D33: PADD 3 | E33: AL04 | F33: AL Birmingham - KM - 2307 | G33: GAS | H33: CPL Path 18 | I33: CPL - Pasadena Injection (Remote) | J33: CPL - Birmingham Delivery Facility | K33: 603 | L33: 131 | M33: 1 | N33: 0 | O33: CPL_Houston-CPL_Birmingham | P33: CPL_0723_99.83.0 | Q33: 0.032955
A34: AL | B34: Birmingham AL | C34: Birmingham AL | D34: PADD 3 | E34: AL04 | F34: AL Birmingham - KM - 2307 | G34: GAS | H34: PPL Path 12 | I34: PPL - Baton Rouge | J34: PPL - Birmingham | K34: 349 | L34: 75.93 | M34: 0 | N34: 0 | O34: PPL_6 | P34: PPL_23_155.38.0_154.17.0 | Q34: 0.028102
A35: AL | B35: Birmingham AL | C35: Birmingham AL | D35: PADD 3 | E35: AL04 | F35: AL Birmingham - KM - 2307 | G35: ETH | H35: CSX USRT PATH 16 | I35: CSX - CSX Indianapolis IN Avon Yard | J35: CSX - CSX Birmingham AL Boyles Yard | K35: 450 | L35: 0 | M35: 0 | N35: 0
A36: AL | B36: Birmingham AL | C36: Birmingham AL | D36: PADD 3 | E36: AL04 | F36: AL Birmingham - KM - 2307 | G36: ETH | H36: CSX USRT PATH 4 | I36: CSX - CSX Chicago IL Bedford Park Yard | J36: CSX - CSX Birmingham AL Boyles Yard | K36: 598 | L36: 0 | M36: 0 | N36: 0
A37: AL | B37: Birmingham AL | C37: Birmingham AL | D37: PADD 3 | E37: AL04 | F37: AL Birmingham - KM - 2307 | G37: ETH | H37: NS Path 117 | I37: NS - NS DECATUR IL | J37: NS - NS Birmingham AL Norris Yard | K37: 631 | L37: 28.7 | M37: 1 | N37: 0 | O37: NS_NS DECATUR IL-NS_NS BIRMINGHAM AL | P37: NS_1023_WB 336649 | Q37: 0.183867
A38: AL | B38: Birmingham AL | C38: Birmingham AL | D38: PADD 3 | E38: AL04 | F38: AL Birmingham - KM - 2307 | G38: ETH | H38: NS USRT PATH 3 | I38: NS - NS Chicago IL Calumet Yard | J38: NS - NS Birmingham AL Norris Yard | K38: 594 | L38: 0 | M38: 0 | N38: 0 | O38: NS_NS Chicago IL-NS_NS BIRMINGHAM AL
A39: AL | B39: Birmingham AL | C39: Birmingham AL | D39: PADD 3 | E39: AL04 | F39: AL Birmingham - KM - 2307 | G39: ETH | H39: NS USRT PATH 9 | I39: NS - NS Clymers IN Anderson Ethanol | J39: NS - NS Birmingham AL Norris Yard | K39: 521 | L39: 0 | M39: 0 | N39: 0
A40: AL | B40: Birmingham AL | C40: Birmingham AL | D40: PADD 3 | E40: AL05 | F40: AL Birmingham - Shell - 2308 | G40: GAS | H40: CPL Path 18 | I40: CPL - Pasadena Injection (Remote) | J40: CPL - Birmingham Delivery Facility | K40: 603 | L40: 131 | M40: 1 | N40: 0 | O40: CPL_Houston-CPL_Birmingham | P40: CPL_0723_99.83.0 | Q40: 0.032955
...

Sheet Tariff Cross Reference
A1: terminal_state | B1: terminal_city_code | C1: terminal_market_code | D1: region | E1: terminal_code | F1: en_terminal_name | G1: published terminal | H1: product_category_code | I1: tariff_code | J1: tariff_library_name | K1: tariff_file_name | L1: tariff_origin | M1: tariff_destination | N1: tariff_value
F2: IL Amboy - Growmark - 3319 | G2: 0 | H2: GAS
F3: TN Dickson - Buckeye - 2244 | G3: 0 | H3: GAS | I3: BP_39 | J3: BP WHD_0723_278.17.0 | K3: TARIFF, FERC NO. 278.17.0 (278.17.0) C000399_T1320.pdf | L3: Whiting . . . . . . . . . . . . . . Indiana | M3: Dickson……..Tennessee (Dickson County) | N3: 0.0715
F4: TN Dickson - Buckeye - 2244 | G4: 0 | H4: GAS | I4: BP_39 | J4: BP WHD_0723_278.17.0 | K4: TARIFF, FERC NO. 278.17.0 (278.17.0) C000399_T1320.pdf | L4: Whiting . . . . . . . . . . . . . . Indiana (Lake County) | M4: Dickson……..Tennessee (Dickson County) | N4: 0.0715
F5: TN Dickson - Buckeye - 2244 | G5: 0 | H5: ETH | I5: CSX_tariff_26 | J5: CSX_1023_estimated | L5: Chicago, IL | N5: 0.183628
F6: TN Knoxville - PBF - 2214-2243 | G6: 0 | H6: ETH | I6: NS_NS DECATUR IL-NS_NS KNOXVILLE TN | J6: NS_1023_WB 336649 | K6: Ethanol Rates Norfolk Southern 5 8 23.pdf | L6: XX XDECATUR, IL GROUP | M6: XX XKNOXVILLE, TN GROU | N6: 0.1979
F7: TX Brownsville - SRPE - 2717 | G7: 0 | H7: ETH | I7: BNSF_tariff_17 | J7: BNSF_1023_estimated | L7: Council Bluffs, IA | N7: 0.292343
F8: TX Midland - Mag - 2766 | G8: 0 | H8: ETH | I8: UP_tariff_208 | J8: UP_1023_estimated | L8: NE - GROUP 3 AGS GROUP | N8: 0.2455
F9: TX Orla - HF Sinclair - 2762 | G9: 0 | H9: ETH | I9: UP_213 | J9: UP_1023_2028-A | K9: UP2028BOOK Ethanol Shipping Rates.pdf | L9: NE - GROUP 3 AGS GROUP | N9: 0.2455
A10: AL | B10: Oxford AL | C10: Anniston/Oxford AL | D10: PADD 3 | E10: AL18 | F10: AL Anniston - Murphy - 2333 | G10: 0 | H10: GAS | I10: CPL_Houston-CPL_Oxford | J10: CPL_0723_99.83.0 | K10: Colonial-FERC-99.83.0.pdf | L10: Houston (Pasadena, Cedar Bayou) Harris County, Texas | M10: Oxford (Calhoun County) | N10: 0.035795
A11: AL | B11: Oxford AL | C11: Anniston/Oxford AL | D11: PADD 3 | E11: AL18 | F11: AL Anniston - Murphy - 2333 | G11: 0 | H11: ETH | I11: NS_NS DECATUR IL-NS_NS ANNISTON AL | J11: NS_1023_WB 336649 | K11: Ethanol Rates Norfolk Southern 5 8 23.pdf | L11: XX XDECATUR, IL GROUP | M11: AL XBIRMINGHAM, AL GRP | N11: 0.183867
A12: AL | B12: Birmingham AL | C12: Birmingham AL | D12: PADD 3 | E12: AL01 | F12: AL Birmingham - Citgo - 2302 | G12: 0 | H12: GAS | I12: CPL_Houston-CPL_Birmingham | J12: CPL_0723_99.83.0 | K12: Colonial-FERC-99.83.0.pdf | L12: Houston (Pasadena, Cedar Bayou) Harris County, Texas | M12: Birmingham (Jefferson County) | N12: 0.032955
A13: AL | B13: Birmingham AL | C13: Birmingham AL | D13: PADD 3 | E13: AL01 | F13: AL Birmingham - Citgo - 2302 | G13: 0 | H13: ETH | I13: NS_NS DECATUR IL-NS_NS BIRMINGHAM AL | J13: NS_1023_WB 336649 | K13: Ethanol Rates Norfolk Southern 5 8 23.pdf | L13: XX XDECATUR, IL GROUP | M13: AL XBIRMINGHAM, AL GRP | N13: 0.183867
A14: AL | B14: Birmingham AL | C14: Birmingham AL | D14: PADD 3 | E14: AL01 | F14: AL Birmingham - Citgo - 2302 | G14: 0 | H14: ETH | I14: NS_NS DECATUR IL-NS_NS BIRMINGHAM AL | J14: NS_1023_WB 336649 | K14: Ethanol Rates Norfolk Southern 5 8 23.pdf | L14: XX XDECATUR, IL GROUP | M14: Birmingham, AL | N14: 0.183867
A15: AL | B15: Birmingham AL | C15: Birmingham AL | D15: PADD 3 | E15: AL03 | F15: AL Birmingham - MPC - 2306 | G15: 0 | H15: GAS | I15: CPL_Houston-CPL_Birmingham | J15: CPL_0723_99.83.0 | K15: Colonial-FERC-99.83.0.pdf | L15: Houston (Pasadena, Cedar Bayou) Harris County, Texas | M15: Birmingham (Jefferson County) | N15: 0.032955
A16: AL | B16: Birmingham AL | C16: Birmingham AL | D16: PADD 3 | E16: AL03 | F16: AL Birmingham - MPC - 2306 | G16: 0 | H16: ETH | I16: NS_NS DECATUR IL-NS_NS BIRMINGHAM AL | J16: NS_1023_WB 336649 | K16: Ethanol Rates Norfolk Southern 5 8 23.pdf | L16: XX XDECATUR, IL GROUP | M16: AL XBIRMINGHAM, AL GRP | N16: 0.183867
A17: AL | B17: Birmingham AL | C17: Birmingham AL | D17: PADD 3 | E17: AL03 | F17: AL Birmingham - MPC - 2306 | G17: 0 | H17: ETH | I17: NS_NS DECATUR IL-NS_NS BIRMINGHAM AL | J17: NS_1023_WB 336649 | K17: Ethanol Rates Norfolk Southern 5 8 23.pdf | L17: XX XDECATUR, IL GROUP | M17: Birmingham, AL | N17: 0.183867
A18: AL | B18: Birmingham AL | C18: Birmingham AL | D18: PADD 3 | E18: AL04 | F18: AL Birmingham - KM - 2307 | G18: 0 | H18: GAS | I18: CPL_Houston-CPL_Birmingham | J18: CPL_0723_99.83.0 | K18: Colonial-FERC-99.83.0.pdf | L18: Houston (Pasadena, Cedar Bayou) Harris County, Texas | M18: Birmingham (Jefferson County) | N18: 0.032955
A19: AL | B19: Birmingham AL | C19: Birmingham AL | D19: PADD 3 | E19: AL04 | F19: AL Birmingham - KM - 2307 | G19: 0 | H19: ETH | I19: NS_NS DECATUR IL-NS_NS BIRMINGHAM AL | J19: NS_1023_WB 336649 | K19: Ethanol Rates Norfolk Southern 5 8 23.pdf | L19: XX XDECATUR, IL GROUP | M19: AL XBIRMINGHAM, AL GRP | N19: 0.183867
A20: AL | B20: Birmingham AL | C20: Birmingham AL | D20: PADD 3 | E20: AL04 | F20: AL Birmingham - KM - 2307 | G20: 0 | H20: ETH | I20: NS_NS DECATUR IL-NS_NS BIRMINGHAM AL | J20: NS_1023_WB 336649 | K20: Ethanol Rates Norfolk Southern 5 8 23.pdf | L20: XX XDECATUR, IL GROUP | M20: Birmingham, AL | N20: 0.183867
A21: AL | B21: Birmingham AL | C21: Birmingham AL | D21: PADD 3 | E21: AL05 | F21: AL Birmingham - Shell - 2308 | G21: 0 | H21: GAS | I21: CPL_Houston-CPL_Birmingham | J21: CPL_0723_99.83.0 | K21: Colonial-FERC-99.83.0.pdf | L21: Houston (Pasadena, Cedar Bayou) Harris County, Texas | M21: Birmingham (Jefferson County) | N21: 0.032955
... A36: AL | B36: Boligee AL | C36: Boligee AL | D36: PADD 3 | E36: AL29 | F36: AL Boligee - ERPC - 0001 | G36: 1 | H36: GAS | I36: CPL_Houston-CPL_Boligee | J36: CPL_0723_99.83.0 | K36: Colonial-FERC-99.83.0.pdf | L36: Houston (Pasadena, Cedar Bayou) Harris County, Texas | M36: Boligee (Greene County) | N36: 0.032955
A37: AL | B37: Boligee AL | C37: Boligee AL | D37: PADD 3 | E37: AL29 | F37: AL Boligee - ERPC - 0001 | G37: 1 | H37: ETH | I37: NS_tariff_1 | J37: NS_1023_estimated | L37: XX XDECATUR, IL GROUP | N37: 0.184845
A38: AL | B38: Mobile AL | C38: Mobile AL | D38: PADD 3 | E38: AL08 | F38: AL Mobile - Mers - 2314 | G38: 0 | H38: ETH | I38: CSX_tariff_52 | J38: CSX_1023_estimated | L38: Chicago, IL | N38: 0.258046
A39: AL | B39: Mobile AL | C39: Mobile AL | D39: PADD 3 | E39: AL10 | F39: AL Mobile - AL Bulk - 2317 | G39: 0 | H39: ETH | I39: CSX_tariff_52 | J39: CSX_1023_estimated | L39: Chicago, IL | N39: 0.258046
A40: AL | B40: Saraland AL | C40: Mobile AL | D40: PADD 3 | E40: AL19 | F40: AL Saraland - Vertex - 2334 | G40: 0 | H40: ETH | I40: CSX_tariff_52 | J40: CSX_1023_estimated | L40: Chicago, IL | N40: 0.258046
A41: AL | B41: Mobile AL | C41: Mobile AL | D41: PADD 3 | E41: AL21 | F41: AL Mobile - Barcliff - 2336 | G41: 0 | H41: ETH | I41: CSX_tariff_52 | J41: CSX_1023_estimated | L41: Chicago, IL | N41: 0.258046
A42: AL | B42: Mobile AL | C42: Mobile AL | D42: PADD 3 | E42: AL23 | F42: AL Mobile - Petro FT - 2339 | G42: 0 | H42: ETH | I42: CSX_tariff_52 | J42: CSX_1023_estimated | L42: Chicago, IL | N42: 0.258046
A43: AL | B43: Mobile AL | C43: Mobile AL | D43: PADD 3 | E43: AL25 | F43: AL Mobile - Martin - 2339 | G43: 0 | H43: ETH | I43: CSX_tariff_52 | J43: CSX_1023_estimated | L43: Chicago, IL | N43: 0.258046
A44: AL | B44: Montgomery AL | C44: Montgomery AL | D44: PADD 3 | E44: AL02 | F44: AL Montgomery - Buckeye - 2304 | G44: 1 | H44: GAS | I44: PPL_22 | J44: PPL_23_155.38.0_154.17.0 | K44: FERC No. 155.38.0 Local Tariff (2023 Index) eff 7-1-2023.pdf | L44: Baton Rouge, LA (East Baton Rouge Parish) | M44: Montgomery, AL (Montgomery County) | N44: 0.035152
A45: AL | B45: Montgomery AL | C45: Montgomery AL | D45: PADD 3 | E45: AL02 | F45: AL Montgomery - Buckeye - 2304 | G45: 1 | H45: ETH | I45: NS_NS PEORIA IL-NS_NS MONTGOMERY AL | J45: NS_1023_WB 336649 | K45: Ethanol Rates Norfolk Southern 5 8 23.pdf | L45: IL XBLOOMINGTON, IL GR | M45: AL XSELMA, AL GROUP | N45: 0.1913
A46: AL | B46: Montgomery AL | C46: Montgomery AL | D46: PADD 3 | E46: AL11 | F46: AL Montgomery - US Oil - 2322 | G46: 0 | H46: GAS | I46: PPL_22 | J46: PPL_23_155.38.0_154.17.0 | K46: FERC No. 155.38.0 Local Tariff (2023 Index) eff 7-1-2023.pdf | L46: Baton Rouge, LA (East Baton Rouge Parish) | M46: Montgomery, AL (Montgomery County) | N46: 0.035152
A47: AL | B47: Montgomery AL | C47: Montgomery AL | D47: PADD 3 | E47: AL11 | F47: AL Montgomery - US Oil - 2322 | G47: 0 | H47: ETH | I47: NS_NS PEORIA IL-NS_NS MONTGOMERY AL | J47: NS_1023_WB 336649 | K47: Ethanol Rates Norfolk Southern 5 8 23.pdf | L47: IL XBLOOMINGTON, IL GR | M47: AL XSELMA, AL GROUP | N47: 0.1913
A48: AL | B48: Montgomery AL | C48: Montgomery AL | D48: PADD 3 | E48: AL12 | F48: AL Montgomery - Vecenergy - 2323 | G48: 0 | H48: GAS | I48: PPL_22 | J48: PPL_23_155.38.0_154.17.0 | K48: FERC No. 155.38.0 Local Tariff (2023 Index) eff 7-1-2023.pdf | L48: Baton Rouge, LA (East Baton Rouge Parish) | M48: Montgomery, AL (Montgomery County) | N48: 0.035152
A49: AL | B49: Montgomery AL | C49: Montgomery AL | D49: PADD 3 | E49: AL12 | F49: AL Montgomery - Vecenergy - 2323 | G49: 0 | H49: ETH | I49: NS_NS PEORIA IL-NS_NS MONTGOMERY AL | J49: NS_1023_WB 336649 | K49: Ethanol Rates Norfolk Southern 5 8 23.pdf | L49: IL XBLOOMINGTON, IL GR | M49: AL XSELMA, AL GROUP | N49: 0.1913
A50: AL | B50: Montgomery AL | C50: Montgomery AL | D50: PADD 3 | E50: AL13 | F50: AL Montgomery - MPC - 2325 | G50: 0 | H50: GAS | I50: PPL_22 | J50: PPL_23_155.38.0_154.17.0 | K50: FERC No. 155.38.0 Local Tariff (2023 Index) eff 7-1-2023.pdf | L50: Baton Rouge, LA (East Baton Rouge Parish) | M50: Montgomery, AL (Montgomery County) | N50: 0.035152
A51: AL | B51: Montgomery AL | C51: Montgomery AL | D51: PADD 3 | E51: AL13 | F51: AL Montgomery - MPC - 2325 | G51: 0 | H51: ETH | I51: NS_NS PEORIA IL-NS_NS MONTGOMERY AL | J51: NS_1023_WB 336649 | K51: Ethanol Rates Norfolk Southern 5 8 23.pdf | L51: IL XBLOOMINGTON, IL GR | M51: AL XSELMA, AL GROUP | N51: 0.1913
A52: AL | B52: Montgomery AL | C52: Montgomery AL | D52: PADD 3 | E52: AL14 | F52: AL Montgomery - Epic - 2326 | G52: 0 | H52: GAS | I52: PPL_22 | J52: PPL_23_155.38.0_154.17.0 | K52: FERC No. 155.38.0 Local Tariff (2023 Index) eff 7-1-2023.pdf | L52: Baton Rouge, LA (East Baton Rouge Parish) | M52: Montgomery, AL (Montgomery County) | N52: 0.035152
A53: AL | B53: Montgomery AL | C53: Montgomery AL | D53: PADD 3 | E53: AL14 | F53: AL Montgomery - Epic - 2326 | G53: 0 | H53: ETH | I53: NS_NS PEORIA IL-NS_NS MONTGOMERY AL | J53: NS_1023_WB 336649 | K53: Ethanol Rates Norfolk Southern 5 8 23.pdf | L53: IL XBLOOMINGTON, IL GR | M53: AL XSELMA, AL GROUP | N53: 0.1913
A54: AL | B54: Montgomery AL | C54: Montgomery AL | D54: PADD 3 | E54: AL15 | F54: AL Montgomery - Murphy - 2327 | G54: 0 | H54: GAS | I54: PPL_22 | J54: PPL_23_155.38.0_154.17.0 | K54: FERC No. 155.38.0 Local Tariff (2023 Index) eff 7-1-2023.pdf | L54: Baton Rouge, LA (East Baton Rouge Parish) | M54: Montgomery, AL (Montgomery County) | N54: 0.035152
...
